<?xml version="1.0"?>
<robot name="penguin" xmlns:xacro="http://ros.org/wiki/xacro">

  <material name="grey">
    <color rgba="0.5 0.5 0.5 1"/>
  </material>

  <link name="base_link">
    <inertial>
      <mass value="1.0"/>
      <origin xyz="0 0 0" rpy="0 0 0"/>
      <inertia ixx="0.1667" ixy="0.0" ixz="0.0" iyy="0.1667" iyz="0.0" izz="0.1667"/>
    </inertial>
    <visual>
      <origin xyz="0 0 0" rpy="0 0 0"/>
      <geometry>
        <sphere radius="0.1"/>
      </geometry>
      <material name="grey"/>
    </visual>
    <collision>
      <origin xyz="0 0 0" rpy="0 0 0"/>
      <geometry>
        <sphere radius="0.1"/>
      </geometry>
    </collision>
  </link>

  <link name="body_link">
    <inertial>
      <mass value="2.0"/>
      <origin xyz="0 0 0.15" rpy="0 0 0"/>
      <inertia ixx="0.023" ixy="0.0" ixz="0.0" iyy="0.023" iyz="0.0" izz="0.046"/>
    </inertial>
    <visual>
      <origin xyz="0 0 0.15" rpy="0 0 0"/>
      <geometry>
        <cylinder length="0.3" radius="0.1"/>
      </geometry>
      <material name="grey"/>
    </visual>
    <collision>
      <origin xyz="0 0 0.15" rpy="0 0 0"/>
      <geometry>
        <cylinder length="0.3" radius="0.1"/>
      </geometry>
    </collision>
  </link>

  <link name="head_link">
    <inertial>
      <mass value="0.5"/>
      <origin xyz="00 0.3" rpy="0 0 0"/>
<inertia ixx="0.005" ixy="0.0" ixz="0.0" iyy="0.005" iyz="0.0" izz="0.005"/>
</inertial>
<visual>
<origin xyz="0 0 0.3" rpy="0 0 0"/>
<geometry>
<box size="0.2 0.2 0.2"/>
</geometry>
<material name="grey"/>
</visual>
<collision>
<origin xyz="0 0 0.3" rpy="0 0 0"/>
<geometry>
<box size="0.2 0.2 0.2"/>
</geometry>
</collision>

  </link>
  <link name="lidar_link">
    <inertial>
      <mass value="0.1"/>
      <origin xyz="0 0 0" rpy="0 0 0"/>
      <inertia ixx="0.0001" ixy="0" ixz="0" iyy="0.0001" iyz="0" izz="0.0001"/>
    </inertial>
    <visual>
      <origin xyz="0 0 -0.05" rpy="0 0 0"/>
      <geometry>
        <mesh filename="lidar.stl"/>
      </geometry>
    </visual>
  </link>
  <link name="realsense_link">
    <inertial>
      <mass value="0.1"/>
      <origin xyz="0 0 0" rpy="0 0 0"/>
      <inertia ixx="0.0001" ixy="0" ixz="0" iyy="0.0001" iyz="0" izz="0.0001"/>
    </inertial>
    <visual>
      <origin xyz="0.06 0 0.05" rpy="0 1.57 0"/>
      <geometry>
        <mesh filename="realsense.stl"/>
      </geometry>
    </visual>
  </link>
  <joint name="base_to_body" type="fixed">
    <origin xyz="0 0 0" rpy="0 0 0"/>
    <parent link="base_link"/>
    <child link="body_link"/>
  </joint>
  <joint name="body_to_head" type="revolute">
    <origin xyz="0 0 0.3" rpy="0 0 0"/>
    <parent link="body_link"/>
    <child link="head_link"/>
    <axis xyz="0 1 0"/>
    <limit effort="10" velocity="1.5" lower="-1.5" upper="1.5"/>
  </joint>
  <joint name="base_to_lidar" type="fixed">
    <parent link="base_link"/>
    <child link="lidar_link"/>
    <origin xyz="0 0 -0.15" rpy="0 0 0"/>
  </joint>
  <joint name="head_to_realsense" type="revolute">
    <parent link="head_link"/>
    <child link="realsense_link"/>
    <origin xyz="0.1 0 0.2" rpy="0 0 0"/>
    <axis xyz="0 1 0"/>
    <limit effort="10" velocity="1.5" lower="-1.5" upper="1.5"/>
</joint>

</robot>
